{"uuid": "888428cb-2611-4a81-87cf-3646acc653a0", "children": ["e9056351-50d3-4d87-a034-653450ab81e0"], "befores": [{"name": "open_app", "status": "passed", "start": 1597052294757, "stop": 1597052324691}], "afters": [{"name": "open_app::0", "status": "broken", "statusDetails": {"message": "selenium.common.exceptions.WebDriverException: Message: An unknown server-side error occurred while processing the command. Original error: Could not proxy. Proxy error: Request failed with status code 404\n\n", "trace": "  File \"D:\\Python38\\lib\\site-packages\\allure_commons\\_allure.py\", line 185, in __call__\n    return self._fixture_function(*args, **kwargs)\n  File \"D:\\Python38\\lib\\site-packages\\_pytest\\fixtures.py\", line 932, in _teardown_yield_fixture\n    next(it)\n  File \"D:\\Pycharm_workspace\\APPV1.0\\TestCases\\conftest.py\", line 47, in open_app\n    driver.close()\n  File \"D:\\Python38\\lib\\site-packages\\selenium\\webdriver\\remote\\webdriver.py\", line 688, in close\n    self.execute(Command.CLOSE)\n  File \"D:\\Python38\\lib\\site-packages\\selenium\\webdriver\\remote\\webdriver.py\", line 321, in execute\n    self.error_handler.check_response(response)\n  File \"D:\\Python38\\lib\\site-packages\\appium\\webdriver\\errorhandler.py\", line 31, in check_response\n    raise wde\n  File \"D:\\Python38\\lib\\site-packages\\appium\\webdriver\\errorhandler.py\", line 26, in check_response\n    super().check_response(response)\n  File \"D:\\Python38\\lib\\site-packages\\selenium\\webdriver\\remote\\errorhandler.py\", line 242, in check_response\n    raise exception_class(message, screen, stacktrace)\n"}, "start": 1597052384330, "stop": 1597052444398}], "start": 1597052294757, "stop": 1597052444399}