{"uuid": "1b1be0ad-640c-4cb2-9652-f4a11b9c584e", "children": ["2ef30f0e-86bf-4023-8ff5-ed0dbb8eab60"], "befores": [{"name": "buy_goods", "status": "broken", "statusDetails": {"message": "selenium.common.exceptions.WebDriverException: Message: An unknown server-side error occurred while processing the command. Original error: The instrumentation process cannot be initialized within 30000ms timeout. Make sure the application under test does not crash and investigate the logcat output. You could also try to increase the value of 'uiautomator2ServerLaunchTimeout' capability. \n\n", "trace": "  File \"D:\\Python38\\lib\\site-packages\\pluggy\\callers.py\", line 187, in _multicall\n    res = hook_impl.function(*args)\n  File \"D:\\Python38\\lib\\site-packages\\_pytest\\fixtures.py\", line 923, in pytest_fixture_setup\n    result = call_fixture_func(fixturefunc, request, kwargs)\n  File \"D:\\Python38\\lib\\site-packages\\_pytest\\fixtures.py\", line 779, in call_fixture_func\n    res = next(it)\n  File \"D:\\Pycharm_workspace\\Hobay\\TestCases\\conftest.py\", line 60, in buy_goods\n    driver = BaseDriver().base_driver(device=request.param)\n  File \"D:\\Pycharm_workspace\\Hobay\\Common\\BaseDriver.py\", line 29, in base_driver\n    driver = webdriver.Remote(\"http://{0}:{1}/wd/hub\".format(i[\"server_url\"], i[\"server_port\"]),\n  File \"D:\\Python38\\lib\\site-packages\\appium\\webdriver\\webdriver.py\", line 140, in __init__\n    super(WebDriver, self).__init__(\n  File \"D:\\Python38\\lib\\site-packages\\selenium\\webdriver\\remote\\webdriver.py\", line 157, in __init__\n    self.start_session(capabilities, browser_profile)\n  File \"D:\\Python38\\lib\\site-packages\\appium\\webdriver\\webdriver.py\", line 219, in start_session\n    response = self.execute(RemoteCommand.NEW_SESSION, parameters)\n  File \"D:\\Python38\\lib\\site-packages\\selenium\\webdriver\\remote\\webdriver.py\", line 321, in execute\n    self.error_handler.check_response(response)\n  File \"D:\\Python38\\lib\\site-packages\\selenium\\webdriver\\remote\\errorhandler.py\", line 242, in check_response\n    raise exception_class(message, screen, stacktrace)\n"}, "start": 1598865893785, "stop": 1598865950123}], "start": 1598865893785, "stop": 1598865950591}